<?xml version="1.0" encoding="utf-8"?>

<robot name="sentry">

  <link name = "base_link" />

  <link name="gimbal_link" />

  <joint name="gimbal_joint" type="floating">
    <parent link="base_link" />
    <child link="gimbal_link" />
  </joint>

  <link name="livox_frame" />

  <joint name="base_joint" type="fixed">
    <origin xyz="0 0.14 0.2" rpy="0 0 0" />
    <parent link="base_link" />
    <child link="livox_frame" />
    <axis xyz= "0 0 0" />
  </joint>
  
  <link name="laser_frame1" />

  <joint name="laser_joint1" type="fixed">
    <origin xyz="0 0.32 0.1" rpy="0 0 0" />
    <parent link="base_link" />
    <child link="laser_frame1" />
    <axis xyz= "0 0 0" />
  </joint>

  <link name="laser_frame2" />

  <joint name="laser_joint2" type="fixed">
    <origin xyz="0.2 0.22 0.1" rpy="0 0 0" />
    <parent link="base_link" />
    <child link="laser_frame2" />
    <axis xyz= "0 0 0" />
  </joint>

</robot>
